Workbook

Sheet How to Use
A1: Eko Power App: Cashier Reporting Template
A2: Owner: Favour, Data and Reporting Assistant | Reviewed by: Head, Power App Unit
A4: Daily routine (by 10am the next working day)
A5: 1. Open Daily Log. Each active cashier already has a row for the day; copy the name block down for each new date.
A6: 2. From each cashier's 6pm WhatsApp report, enter: Report Received, Time Received, Transactions, Total Collected, NKCG amount and Closing Wallet Balance.
A7: 3. If a cashier sends nothing, set Report Received to "No". The row shows "Missed" in red.
A8: 4. District, cashier type, on-time status, commission and wallet zeroization fill in automatically.
A9: 5. Send the Head of Unit a list of missed or late reports and wallets not zeroized.
A11: Rules built into the sheet
A12: • Reports after 6pm show "Late". Change the deadline on the Settings tab if it moves.
A13: • Transactions from unreported days do not count toward totals or incentives.
A14: • A wallet is zeroized only when the closing balance is ₦0.
... A24: • Pale gold cells are inputs. White cells are formulas, so don't type over them.

Sheet Cashier Roster
A1: Cashier Roster
A2: Every cashier, their district and type. Only "Active" cashiers count as expected reporters.
A4: S/N | B4: Cashier Name | C4: District | D4: Cashier Type | E4: Zone (if zone cashier) | F4: Wallet Account Number | G4: Email Address | H4: Roster Status | I4: Notes
A5: =IF(B5="","",ROW()-4) -> 1 | B5: Augustine Oyathelemhi | C5: Agbara | D5: District cashier | F5: 9710558699 | G5: oyathelemhiaugustine@gmail.com | H5: Active
A6: =IF(B6="","",ROW()-4) -> 2 | B6: Otun Fausat | C6: Agbara | D6: Zone cashier (new) | F6: 9711012544 | G6: otun.fausat@gmail.com | H6: Active
A7: =IF(B7="","",ROW()-4) -> 3 | B7: Taiwo Noimot | C7: Ajah | D7: District cashier | F7: 9710574350 | G7: Customercare.ajah@ekedp.com | H7: Active
A8: =IF(B8="","",ROW()-4) -> 4 | B8: Taiwo Akintoye | C8: Ajele | D8: District cashier | F8: 9710574252 | G8: Customercare.ajele@ekedp.com | H8: Active
A9: =IF(B9="","",ROW()-4) -> 5 | B9: Mary Agbim | C9: Ajele | D9: Zone cashier (new) | F9: 9711021008 | H9: Active | I9: Email not yet provided
A10: =IF(B10="","",ROW()-4) -> 6 | B10: Ojulari Waheed | C10: Apapa | D10: District cashier | F10: 9710574813 | G10: Customercare.apapa@ekedp.com | H10: Active
A11: =IF(B11="","",ROW()-4) -> 7 | B11: Ikudehinbo Oluwatosin | C11: Apapa | D11: Zone cashier (new) | F11: 9711011787 | G11: Oluwatomisinabiodun1@Gmail.com | H11: Active | I11: Wallet list spells it "Ikudehinbu Tosin"; confirm spelling
A12: =IF(B12="","",ROW()-4) -> 8 | B12: Onileowo Victoria | C12: Festac | D12: District cashier | F12: 9710581761 | G12: Customercare.festac@ekedp.com | H12: Active
A13: =IF(B13="","",ROW()-4) -> 9 | B13: Oluwaseyi Ajayi | C13: Festac | D13: Zone cashier (new) | F13: 9711034575 | G13: bettyseyi9@gmail.com | H13: Active | I13: Previously listed as Seyi Ajayi
A14: =IF(B14="","",ROW()-4) -> 10 | B14: Okiji Olubunmi Jacob | C14: Ibeju | D14: District cashier | F14: 9710695871 | G14: customercare.ibeju@ekedp.com | H14: Active
A15: =IF(B15="","",ROW()-4) -> 11 | B15: Adebari Temitayo | C15: Ijora | D15: District cashier | F15: 9710592553 | G15: customercare.ijora@ekedp.com | H15: Active
A16: =IF(B16="","",ROW()-4) -> 12 | B16: Ibeto Catherine | C16: Ijora | D16: Zone cashier (new) | F16: 9711067628 | H16: Active | I16: Wallet name reads "Mycron Electric Limited/EKEDP Mushin District" but she is listed under Ijora; confirm district. Email not yet provided
A17: =IF(B17="","",ROW()-4) -> 13 | B17: Olukoya Olanrewaju | C17: Island | D17: District cashier | F17: 9710610766 | G17: serenaolanrewaju@gmail.com | H17: Active
A18: =IF(B18="","",ROW()-4) -> 14 | B18: Aromire Olasumbo (Azizat) | C18: Island | D18: District cashier | F18: 9710601945 | G18: customercare.Islands@ekedp.com | H18: Active
A19: =IF(B19="","",ROW()-4) -> 15 | B19: Kareem Idowu | C19: Lekki | D19: District cashier | F19: 9710650044 | H19: Active | I19: Wallet name: Mycron Electric Limited EKEDP/Orgf. Also recorded as Kareem Balkis; confirm. Email not yet provided
A20: =IF(B20="","",ROW()-4) -> 16 | B20: Caroline Francis | C20: Mushin | D20: District cashier | F20: 9710573949 | G20: customercare.mushin@ekedp.com | H20: Active
A21: =IF(B21="","",ROW()-4) -> 17 | B21: Siyanbola Abosede | C21: Mushin | D21: Zone cashier (new) | F21: 9711011484 | G21: olamide4navy@gmail.com | H21: Active | I21: Confirm email (name on address differs)
A22: =IF(B22="","",ROW()-4) -> 18 | B22: Oke James | C22: Ojo | D22: District cashier | F22: 9710614370 | G22: okejamesadekunle@gmail.com | H22: Active
A23: =IF(B23="","",ROW()-4) -> 19 | B23: Tosin Onadele | C23: Ojo | D23: Zone cashier (new) | F23: 9711020376 | G23: Tosin.onadele@ekedp.com | H23: Active | I23: New Ojo zone cashier, confirmed from wallet list
A24: =IF(B24="","",ROW()-4) -> 20 | B24: Shodeke Oluwabanke | C24: Orile | D24: District cashier | F24: 9710592795 | G24: Customercare.orile@ekedp.com | H24: Active
A25: =IF(B25="","",ROW()-4) -> 21 | B25: Maryjane (Lekki cover) | C25: Lekki | D25: District cashier | H25: To confirm | I25: July maternity cover: confirm surname and whether still in role
A26: =IF(B26="","",ROW()-4) -> 22 | B26: Amaegwu Chioma Precious | C26: Orile | D26: District cashier | H26: Pending | I26: Recommended for redeployment to Orile; awaiting confirmation
A27: =IF(B27="","",ROW()-4)
A28: =IF(B28="","",ROW()-4)
A29: =IF(B29="","",ROW()-4)
A30: =IF(B30="","",ROW()-4)
A31: =IF(B31="","",ROW()-4)
A32: =IF(B32="","",ROW()-4)
A33: =IF(B33="","",ROW()-4)
A34: =IF(B34="","",ROW()-4)
A35: =IF(B35="","",ROW()-4)
A36: =IF(B36="","",ROW()-4)
A37: =IF(B37="","",ROW()-4)
A38: =IF(B38="","",ROW()-4)
... A64: =IF(B64="","",ROW()-4)

Sheet Daily Log
A1: Daily Cashier Report Log
A2: One row per cashier per day, copied from the 6pm WhatsApp reports. Pale gold cells: fill in. White cells: automatic.
A4: Date | B4: Cashier Name | C4: District | D4: Cashier Type | E4: Report Received? | F4: Time Received | G4: On Time? | H4: No. of Transactions | I4: Total Collected (₦) | J4: of which NKCG (₦) | K4: Commission Earned (₦) | L4: Closing Wallet Balance (₦) | M4: Wallet Zeroized? | N4: Remarks
A5: 46315 | B5: Augustine Oyathelemhi | C5: =IF(B5="","",IFERROR(INDEX('Cashier Roster'!$C$5:$C$64,MATCH(B5,'Cashier Roster'!$B$5:$B$64,0)),"Not on roster")) -> Agbara | D5: =IF(B5="","",IFERROR(INDEX('Cashier Roster'!$D$5:$D$64,MATCH(B5,'Cashier Roster'!$B$5:$B$64,0)),"")) -> District cashier | G5: =IF(OR(B5="",E5=""),"",IF(E5="No","Missed",IF(F5="","",IF(F5<=Settings!$B$7,"On time","Late")))) | K5: =IF(J5="","",ROUND(J5*Settings!$B$8,2)) | M5: =IF(L5="","",IF(L5<=0,"Yes","No")) | N5: Rows pre-filled for 20/10/2026. Copy the name block down for each new day.
A6: 46315 | B6: Otun Fausat | C6: =IF(B6="","",IFERROR(INDEX('Cashier Roster'!$C$5:$C$64,MATCH(B6,'Cashier Roster'!$B$5:$B$64,0)),"Not on roster")) -> Agbara | D6: =IF(B6="","",IFERROR(INDEX('Cashier Roster'!$D$5:$D$64,MATCH(B6,'Cashier Roster'!$B$5:$B$64,0)),"")) -> Zone cashier (new) | G6: =IF(OR(B6="",E6=""),"",IF(E6="No","Missed",IF(F6="","",IF(F6<=Settings!$B$7,"On time","Late")))) | K6: =IF(J6="","",ROUND(J6*Settings!$B$8,2)) | M6: =IF(L6="","",IF(L6<=0,"Yes","No"))
A7: 46315 | B7: Taiwo Noimot | C7: =IF(B7="","",IFERROR(INDEX('Cashier Roster'!$C$5:$C$64,MATCH(B7,'Cashier Roster'!$B$5:$B$64,0)),"Not on roster")) -> Ajah | D7: =IF(B7="","",IFERROR(INDEX('Cashier Roster'!$D$5:$D$64,MATCH(B7,'Cashier Roster'!$B$5:$B$64,0)),"")) -> District cashier | G7: =IF(OR(B7="",E7=""),"",IF(E7="No","Missed",IF(F7="","",IF(F7<=Settings!$B$7,"On time","Late")))) | K7: =IF(J7="","",ROUND(J7*Settings!$B$8,2)) | M7: =IF(L7="","",IF(L7<=0,"Yes","No"))
A8: 46315 | B8: Taiwo Akintoye | C8: =IF(B8="","",IFERROR(INDEX('Cashier Roster'!$C$5:$C$64,MATCH(B8,'Cashier Roster'!$B$5:$B$64,0)),"Not on roster")) -> Ajele | D8: =IF(B8="","",IFERROR(INDEX('Cashier Roster'!$D$5:$D$64,MATCH(B8,'Cashier Roster'!$B$5:$B$64,0)),"")) -> District cashier | G8: =IF(OR(B8="",E8=""),"",IF(E8="No","Missed",IF(F8="","",IF(F8<=Settings!$B$7,"On time","Late")))) | K8: =IF(J8="","",ROUND(J8*Settings!$B$8,2)) | M8: =IF(L8="","",IF(L8<=0,"Yes","No"))
A9: 46315 | B9: Mary Agbim | C9: =IF(B9="","",IFERROR(INDEX('Cashier Roster'!$C$5:$C$64,MATCH(B9,'Cashier Roster'!$B$5:$B$64,0)),"Not on roster")) -> Ajele | D9: =IF(B9="","",IFERROR(INDEX('Cashier Roster'!$D$5:$D$64,MATCH(B9,'Cashier Roster'!$B$5:$B$64,0)),"")) -> Zone cashier (new) | G9: =IF(OR(B9="",E9=""),"",IF(E9="No","Missed",IF(F9="","",IF(F9<=Settings!$B$7,"On time","Late")))) | K9: =IF(J9="","",ROUND(J9*Settings!$B$8,2)) | M9: =IF(L9="","",IF(L9<=0,"Yes","No"))
A10: 46315 | B10: Ojulari Waheed | C10: =IF(B10="","",IFERROR(INDEX('Cashier Roster'!$C$5:$C$64,MATCH(B10,'Cashier Roster'!$B$5:$B$64,0)),"Not on roster")) -> Apapa | D10: =IF(B10="","",IFERROR(INDEX('Cashier Roster'!$D$5:$D$64,MATCH(B10,'Cashier Roster'!$B$5:$B$64,0)),"")) -> District cashier | G10: =IF(OR(B10="",E10=""),"",IF(E10="No","Missed",IF(F10="","",IF(F10<=Settings!$B$7,"On time","Late")))) | K10: =IF(J10="","",ROUND(J10*Settings!$B$8,2)) | M10: =IF(L10="","",IF(L10<=0,"Yes","No"))
A11: 46315 | B11: Ikudehinbo Oluwatosin | C11: =IF(B11="","",IFERROR(INDEX('Cashier Roster'!$C$5:$C$64,MATCH(B11,'Cashier Roster'!$B$5:$B$64,0)),"Not on roster")) -> Apapa | D11: =IF(B11="","",IFERROR(INDEX('Cashier Roster'!$D$5:$D$64,MATCH(B11,'Cashier Roster'!$B$5:$B$64,0)),"")) -> Zone cashier (new) | G11: =IF(OR(B11="",E11=""),"",IF(E11="No","Missed",IF(F11="","",IF(F11<=Settings!$B$7,"On time","Late")))) | K11: =IF(J11="","",ROUND(J11*Settings!$B$8,2)) | M11: =IF(L11="","",IF(L11<=0,"Yes","No"))
A12: 46315 | B12: Onileowo Victoria | C12: =IF(B12="","",IFERROR(INDEX('Cashier Roster'!$C$5:$C$64,MATCH(B12,'Cashier Roster'!$B$5:$B$64,0)),"Not on roster")) -> Festac | D12: =IF(B12="","",IFERROR(INDEX('Cashier Roster'!$D$5:$D$64,MATCH(B12,'Cashier Roster'!$B$5:$B$64,0)),"")) -> District cashier | G12: =IF(OR(B12="",E12=""),"",IF(E12="No","Missed",IF(F12="","",IF(F12<=Settings!$B$7,"On time","Late")))) | K12: =IF(J12="","",ROUND(J12*Settings!$B$8,2)) | M12: =IF(L12="","",IF(L12<=0,"Yes","No"))
A13: 46315 | B13: Oluwaseyi Ajayi | C13: =IF(B13="","",IFERROR(INDEX('Cashier Roster'!$C$5:$C$64,MATCH(B13,'Cashier Roster'!$B$5:$B$64,0)),"Not on roster")) -> Festac | D13: =IF(B13="","",IFERROR(INDEX('Cashier Roster'!$D$5:$D$64,MATCH(B13,'Cashier Roster'!$B$5:$B$64,0)),"")) -> Zone cashier (new) | G13: =IF(OR(B13="",E13=""),"",IF(E13="No","Missed",IF(F13="","",IF(F13<=Settings!$B$7,"On time","Late")))) | K13: =IF(J13="","",ROUND(J13*Settings!$B$8,2)) | M13: =IF(L13="","",IF(L13<=0,"Yes","No"))
A14: 46315 | B14: Okiji Olubunmi Jacob | C14: =IF(B14="","",IFERROR(INDEX('Cashier Roster'!$C$5:$C$64,MATCH(B14,'Cashier Roster'!$B$5:$B$64,0)),"Not on roster")) -> Ibeju | D14: =IF(B14="","",IFERROR(INDEX('Cashier Roster'!$D$5:$D$64,MATCH(B14,'Cashier Roster'!$B$5:$B$64,0)),"")) -> District cashier | G14: =IF(OR(B14="",E14=""),"",IF(E14="No","Missed",IF(F14="","",IF(F14<=Settings!$B$7,"On time","Late")))) | K14: =IF(J14="","",ROUND(J14*Settings!$B$8,2)) | M14: =IF(L14="","",IF(L14<=0,"Yes","No"))
A15: 46315 | B15: Adebari Temitayo | C15: =IF(B15="","",IFERROR(INDEX('Cashier Roster'!$C$5:$C$64,MATCH(B15,'Cashier Roster'!$B$5:$B$64,0)),"Not on roster")) -> Ijora | D15: =IF(B15="","",IFERROR(INDEX('Cashier Roster'!$D$5:$D$64,MATCH(B15,'Cashier Roster'!$B$5:$B$64,0)),"")) -> District cashier | G15: =IF(OR(B15="",E15=""),"",IF(E15="No","Missed",IF(F15="","",IF(F15<=Settings!$B$7,"On time","Late")))) | K15: =IF(J15="","",ROUND(J15*Settings!$B$8,2)) | M15: =IF(L15="","",IF(L15<=0,"Yes","No"))
A16: 46315 | B16: Ibeto Catherine | C16: =IF(B16="","",IFERROR(INDEX('Cashier Roster'!$C$5:$C$64,MATCH(B16,'Cashier Roster'!$B$5:$B$64,0)),"Not on roster")) -> Ijora | D16: =IF(B16="","",IFERROR(INDEX('Cashier Roster'!$D$5:$D$64,MATCH(B16,'Cashier Roster'!$B$5:$B$64,0)),"")) -> Zone cashier (new) | G16: =IF(OR(B16="",E16=""),"",IF(E16="No","Missed",IF(F16="","",IF(F16<=Settings!$B$7,"On time","Late")))) | K16: =IF(J16="","",ROUND(J16*Settings!$B$8,2)) | M16: =IF(L16="","",IF(L16<=0,"Yes","No"))
A17: 46315 | B17: Olukoya Olanrewaju | C17: =IF(B17="","",IFERROR(INDEX('Cashier Roster'!$C$5:$C$64,MATCH(B17,'Cashier Roster'!$B$5:$B$64,0)),"Not on roster")) -> Island | D17: =IF(B17="","",IFERROR(INDEX('Cashier Roster'!$D$5:$D$64,MATCH(B17,'Cashier Roster'!$B$5:$B$64,0)),"")) -> District cashier | G17: =IF(OR(B17="",E17=""),"",IF(E17="No","Missed",IF(F17="","",IF(F17<=Settings!$B$7,"On time","Late")))) | K17: =IF(J17="","",ROUND(J17*Settings!$B$8,2)) | M17: =IF(L17="","",IF(L17<=0,"Yes","No"))
... A24: 46315 | B24: Shodeke Oluwabanke | C24: =IF(B24="","",IFERROR(INDEX('Cashier Roster'!$C$5:$C$64,MATCH(B24,'Cashier Roster'!$B$5:$B$64,0)),"Not on roster")) -> Orile | D24: =IF(B24="","",IFERROR(INDEX('Cashier Roster'!$D$5:$D$64,MATCH(B24,'Cashier Roster'!$B$5:$B$64,0)),"")) -> District cashier | G24: =IF(OR(B24="",E24=""),"",IF(E24="No","Missed",IF(F24="","",IF(F24<=Settings!$B$7,"On time","Late")))) | K24: =IF(J24="","",ROUND(J24*Settings!$B$8,2)) | M24: =IF(L24="","",IF(L24<=0,"Yes","No"))
C25: =IF(B25="","",IFERROR(INDEX('Cashier Roster'!$C$5:$C$64,MATCH(B25,'Cashier Roster'!$B$5:$B$64,0)),"Not on roster")) | D25: =IF(B25="","",IFERROR(INDEX('Cashier Roster'!$D$5:$D$64,MATCH(B25,'Cashier Roster'!$B$5:$B$64,0)),"")) | G25: =IF(OR(B25="",E25=""),"",IF(E25="No","Missed",IF(F25="","",IF(F25<=Settings!$B$7,"On time","Late")))) | K25: =IF(J25="","",ROUND(J25*Settings!$B$8,2)) | M25: =IF(L25="","",IF(L25<=0,"Yes","No"))
C26: =IF(B26="","",IFERROR(INDEX('Cashier Roster'!$C$5:$C$64,MATCH(B26,'Cashier Roster'!$B$5:$B$64,0)),"Not on roster")) | D26: =IF(B26="","",IFERROR(INDEX('Cashier Roster'!$D$5:$D$64,MATCH(B26,'Cashier Roster'!$B$5:$B$64,0)),"")) | G26: =IF(OR(B26="",E26=""),"",IF(E26="No","Missed",IF(F26="","",IF(F26<=Settings!$B$7,"On time","Late")))) | K26: =IF(J26="","",ROUND(J26*Settings!$B$8,2)) | M26: =IF(L26="","",IF(L26<=0,"Yes","No"))
C27: =IF(B27="","",IFERROR(INDEX('Cashier Roster'!$C$5:$C$64,MATCH(B27,'Cashier Roster'!$B$5:$B$64,0)),"Not on roster")) | D27: =IF(B27="","",IFERROR(INDEX('Cashier Roster'!$D$5:$D$64,MATCH(B27,'Cashier Roster'!$B$5:$B$64,0)),"")) | G27: =IF(OR(B27="",E27=""),"",IF(E27="No","Missed",IF(F27="","",IF(F27<=Settings!$B$7,"On time","Late")))) | K27: =IF(J27="","",ROUND(J27*Settings!$B$8,2)) | M27: =IF(L27="","",IF(L27<=0,"Yes","No"))
C28: =IF(B28="","",IFERROR(INDEX('Cashier Roster'!$C$5:$C$64,MATCH(B28,'Cashier Roster'!$B$5:$B$64,0)),"Not on roster")) | D28: =IF(B28="","",IFERROR(INDEX('Cashier Roster'!$D$5:$D$64,MATCH(B28,'Cashier Roster'!$B$5:$B$64,0)),"")) | G28: =IF(OR(B28="",E28=""),"",IF(E28="No","Missed",IF(F28="","",IF(F28<=Settings!$B$7,"On time","Late")))) | K28: =IF(J28="","",ROUND(J28*Settings!$B$8,2)) | M28: =IF(L28="","",IF(L28<=0,"Yes","No"))
C29: =IF(B29="","",IFERROR(INDEX('Cashier Roster'!$C$5:$C$64,MATCH(B29,'Cashier Roster'!$B$5:$B$64,0)),"Not on roster")) | D29: =IF(B29="","",IFERROR(INDEX('Cashier Roster'!$D$5:$D$64,MATCH(B29,'Cashier Roster'!$B$5:$B$64,0)),"")) | G29: =IF(OR(B29="",E29=""),"",IF(E29="No","Missed",IF(F29="","",IF(F29<=Settings!$B$7,"On time","Late")))) | K29: =IF(J29="","",ROUND(J29*Settings!$B$8,2)) | M29: =IF(L29="","",IF(L29<=0,"Yes","No"))
C30: =IF(B30="","",IFERROR(INDEX('Cashier Roster'!$C$5:$C$64,MATCH(B30,'Cashier Roster'!$B$5:$B$64,0)),"Not on roster")) | D30: =IF(B30="","",IFERROR(INDEX('Cashier Roster'!$D$5:$D$64,MATCH(B30,'Cashier Roster'!$B$5:$B$64,0)),"")) | G30: =IF(OR(B30="",E30=""),"",IF(E30="No","Missed",IF(F30="","",IF(F30<=Settings!$B$7,"On time","Late")))) | K30: =IF(J30="","",ROUND(J30*Settings!$B$8,2)) | M30: =IF(L30="","",IF(L30<=0,"Yes","No"))
C31: =IF(B31="","",IFERROR(INDEX('Cashier Roster'!$C$5:$C$64,MATCH(B31,'Cashier Roster'!$B$5:$B$64,0)),"Not on roster")) | D31: =IF(B31="","",IFERROR(INDEX('Cashier Roster'!$D$5:$D$64,MATCH(B31,'Cashier Roster'!$B$5:$B$64,0)),"")) | G31: =IF(OR(B31="",E31=""),"",IF(E31="No","Missed",IF(F31="","",IF(F31<=Settings!$B$7,"On time","Late")))) | K31: =IF(J31="","",ROUND(J31*Settings!$B$8,2)) | M31: =IF(L31="","",IF(L31<=0,"Yes","No"))
C32: =IF(B32="","",IFERROR(INDEX('Cashier Roster'!$C$5:$C$64,MATCH(B32,'Cashier Roster'!$B$5:$B$64,0)),"Not on roster")) | D32: =IF(B32="","",IFERROR(INDEX('Cashier Roster'!$D$5:$D$64,MATCH(B32,'Cashier Roster'!$B$5:$B$64,0)),"")) | G32: =IF(OR(B32="",E32=""),"",IF(E32="No","Missed",IF(F32="","",IF(F32<=Settings!$B$7,"On time","Late")))) | K32: =IF(J32="","",ROUND(J32*Settings!$B$8,2)) | M32: =IF(L32="","",IF(L32<=0,"Yes","No"))
C33: =IF(B33="","",IFERROR(INDEX('Cashier Roster'!$C$5:$C$64,MATCH(B33,'Cashier Roster'!$B$5:$B$64,0)),"Not on roster")) | D33: =IF(B33="","",IFERROR(INDEX('Cashier Roster'!$D$5:$D$64,MATCH(B33,'Cashier Roster'!$B$5:$B$64,0)),"")) | G33: =IF(OR(B33="",E33=""),"",IF(E33="No","Missed",IF(F33="","",IF(F33<=Settings!$B$7,"On time","Late")))) | K33: =IF(J33="","",ROUND(J33*Settings!$B$8,2)) | M33: =IF(L33="","",IF(L33<=0,"Yes","No"))
C34: =IF(B34="","",IFERROR(INDEX('Cashier Roster'!$C$5:$C$64,MATCH(B34,'Cashier Roster'!$B$5:$B$64,0)),"Not on roster")) | D34: =IF(B34="","",IFERROR(INDEX('Cashier Roster'!$D$5:$D$64,MATCH(B34,'Cashier Roster'!$B$5:$B$64,0)),"")) | G34: =IF(OR(B34="",E34=""),"",IF(E34="No","Missed",IF(F34="","",IF(F34<=Settings!$B$7,"On time","Late")))) | K34: =IF(J34="","",ROUND(J34*Settings!$B$8,2)) | M34: =IF(L34="","",IF(L34<=0,"Yes","No"))
C35: =IF(B35="","",IFERROR(INDEX('Cashier Roster'!$C$5:$C$64,MATCH(B35,'Cashier Roster'!$B$5:$B$64,0)),"Not on roster")) | D35: =IF(B35="","",IFERROR(INDEX('Cashier Roster'!$D$5:$D$64,MATCH(B35,'Cashier Roster'!$B$5:$B$64,0)),"")) | G35: =IF(OR(B35="",E35=""),"",IF(E35="No","Missed",IF(F35="","",IF(F35<=Settings!$B$7,"On time","Late")))) | K35: =IF(J35="","",ROUND(J35*Settings!$B$8,2)) | M35: =IF(L35="","",IF(L35<=0,"Yes","No"))
C36: =IF(B36="","",IFERROR(INDEX('Cashier Roster'!$C$5:$C$64,MATCH(B36,'Cashier Roster'!$B$5:$B$64,0)),"Not on roster")) | D36: =IF(B36="","",IFERROR(INDEX('Cashier Roster'!$D$5:$D$64,MATCH(B36,'Cashier Roster'!$B$5:$B$64,0)),"")) | G36: =IF(OR(B36="",E36=""),"",IF(E36="No","Missed",IF(F36="","",IF(F36<=Settings!$B$7,"On time","Late")))) | K36: =IF(J36="","",ROUND(J36*Settings!$B$8,2)) | M36: =IF(L36="","",IF(L36<=0,"Yes","No"))
... C4004: =IF(B4004="","",IFERROR(INDEX('Cashier Roster'!$C$5:$C$64,MATCH(B4004,'Cashier Roster'!$B$5:$B$64,0)),"Not on roster")) | D4004: =IF(B4004="","",IFERROR(INDEX('Cashier Roster'!$D$5:$D$64,MATCH(B4004,'Cashier Roster'!$B$5:$B$64,0)),"")) | G4004: =IF(OR(B4004="",E4004=""),"",IF(E4004="No","Missed",IF(F4004="","",IF(F4004<=Settings!$B$7,"On time","Late")))) | K4004: =IF(J4004="","",ROUND(J4004*Settings!$B$8,2)) | M4004: =IF(L4004="","",IF(L4004<=0,"Yes","No"))

Sheet Cashier Summary
A1: Cashier Performance Summary
A2: For the period set on the Settings tab. Ranked by total collected. Only reported transactions count toward incentives.
A3: =" Period: "&TEXT(Settings!$B$5,"dd/mm/yyyy")&" to "&TEXT(Settings!$B$6,"dd/mm/yyyy") -> Period: 01/10/2026 to 31/10/2026
A5: Cashier Name | B5: District | C5: Cashier Type | D5: Status | E5: Days Logged | F5: Reports Received | G5: On Time | H5: On-Time Rate | I5: Transactions | J5: Total Collected (₦) | K5: NKCG (₦) | L5: Commission (₦) | M5: Days Zeroized | N5: Zeroization Rate | O5: Rank
A6: =IF('Cashier Roster'!B5="","",'Cashier Roster'!B5) -> Augustine Oyathelemhi | B6: =IF(A6="","",'Cashier Roster'!C5) -> Agbara | C6: =IF(A6="","",'Cashier Roster'!D5) -> District cashier | D6: =IF(A6="","",'Cashier Roster'!H5) -> Active | E6: =IF(A6="","",COUNTIFS('Daily Log'!$B$5:$B$4004,A6,'Daily Log'!$A$5:$A$4004,">="&Settings!$B$5,'Daily Log'!$A$5:$A$4004,"<="&Settings!$B$6)) -> 1 | F6: =IF(A6="","",COUNTIFS('Daily Log'!$B$5:$B$4004,A6,'Daily Log'!$A$5:$A$4004,">="&Settings!$B$5,'Daily Log'!$A$5:$A$4004,"<="&Settings!$B$6,'Daily Log'!$E$5:$E$4004,"Yes")) -> 0 | G6: =IF(A6="","",COUNTIFS('Daily Log'!$B$5:$B$4004,A6,'Daily Log'!$A$5:$A$4004,">="&Settings!$B$5,'Daily Log'!$A$5:$A$4004,"<="&Settings!$B$6,'Daily Log'!$G$5:$G$4004,"On time")) -> 0 | H6: =IF(OR(A6="",E6=0),"",G6/E6) -> 0 | I6: =IF(A6="","",SUMIFS('Daily Log'!$H$5:$H$4004,'Daily Log'!$B$5:$B$4004,A6,'Daily Log'!$A$5:$A$4004,">="&Settings!$B$5,'Daily Log'!$A$5:$A$4004,"<="&Settings!$B$6,'Daily Log'!$E$5:$E$4004,"Yes")) -> 0 | J6: =IF(A6="","",SUMIFS('Daily Log'!$I$5:$I$4004,'Daily Log'!$B$5:$B$4004,A6,'Daily Log'!$A$5:$A$4004,">="&Settings!$B$5,'Daily Log'!$A$5:$A$4004,"<="&Settings!$B$6,'Daily Log'!$E$5:$E$4004,"Yes")) -> 0 | K6: =IF(A6="","",SUMIFS('Daily Log'!$J$5:$J$4004,'Daily Log'!$B$5:$B$4004,A6,'Daily Log'!$A$5:$A$4004,">="&Settings!$B$5,'Daily Log'!$A$5:$A$4004,"<="&Settings!$B$6,'Daily Log'!$E$5:$E$4004,"Yes")) -> 0 | L6: =IF(A6="","",SUMIFS('Daily Log'!$K$5:$K$4004,'Daily Log'!$B$5:$B$4004,A6,'Daily Log'!$A$5:$A$4004,">="&Settings!$B$5,'Daily Log'!$A$5:$A$4004,"<="&Settings!$B$6,'Daily Log'!$E$5:$E$4004,"Yes")) -> 0 | M6: =IF(A6="","",COUNTIFS('Daily Log'!$B$5:$B$4004,A6,'Daily Log'!$A$5:$A$4004,">="&Settings!$B$5,'Daily Log'!$A$5:$A$4004,"<="&Settings!$B$6,'Daily Log'!$M$5:$M$4004,"Yes")) -> 0 | N6: =IF(OR(A6="",E6=0),"",M6/E6) -> 0 | O6: =IF(OR(A6="",N(J6)=0),"",COUNTIF($J$6:$J$65,">"&J6)+1)
A7: =IF('Cashier Roster'!B6="","",'Cashier Roster'!B6) -> Otun Fausat | B7: =IF(A7="","",'Cashier Roster'!C6) -> Agbara | C7: =IF(A7="","",'Cashier Roster'!D6) -> Zone cashier (new) | D7: =IF(A7="","",'Cashier Roster'!H6) -> Active | E7: =IF(A7="","",COUNTIFS('Daily Log'!$B$5:$B$4004,A7,'Daily Log'!$A$5:$A$4004,">="&Settings!$B$5,'Daily Log'!$A$5:$A$4004,"<="&Settings!$B$6)) -> 1 | F7: =IF(A7="","",COUNTIFS('Daily Log'!$B$5:$B$4004,A7,'Daily Log'!$A$5:$A$4004,">="&Settings!$B$5,'Daily Log'!$A$5:$A$4004,"<="&Settings!$B$6,'Daily Log'!$E$5:$E$4004,"Yes")) -> 0 | G7: =IF(A7="","",COUNTIFS('Daily Log'!$B$5:$B$4004,A7,'Daily Log'!$A$5:$A$4004,">="&Settings!$B$5,'Daily Log'!$A$5:$A$4004,"<="&Settings!$B$6,'Daily Log'!$G$5:$G$4004,"On time")) -> 0 | H7: =IF(OR(A7="",E7=0),"",G7/E7) -> 0 | I7: =IF(A7="","",SUMIFS('Daily Log'!$H$5:$H$4004,'Daily Log'!$B$5:$B$4004,A7,'Daily Log'!$A$5:$A$4004,">="&Settings!$B$5,'Daily Log'!$A$5:$A$4004,"<="&Settings!$B$6,'Daily Log'!$E$5:$E$4004,"Yes")) -> 0 | J7: =IF(A7="","",SUMIFS('Daily Log'!$I$5:$I$4004,'Daily Log'!$B$5:$B$4004,A7,'Daily Log'!$A$5:$A$4004,">="&Settings!$B$5,'Daily Log'!$A$5:$A$4004,"<="&Settings!$B$6,'Daily Log'!$E$5:$E$4004,"Yes")) -> 0 | K7: =IF(A7="","",SUMIFS('Daily Log'!$J$5:$J$4004,'Daily Log'!$B$5:$B$4004,A7,'Daily Log'!$A$5:$A$4004,">="&Settings!$B$5,'Daily Log'!$A$5:$A$4004,"<="&Settings!$B$6,'Daily Log'!$E$5:$E$4004,"Yes")) -> 0 | L7: =IF(A7="","",SUMIFS('Daily Log'!$K$5:$K$4004,'Daily Log'!$B$5:$B$4004,A7,'Daily Log'!$A$5:$A$4004,">="&Settings!$B$5,'Daily Log'!$A$5:$A$4004,"<="&Settings!$B$6,'Daily Log'!$E$5:$E$4004,"Yes")) -> 0 | M7: =IF(A7="","",COUNTIFS('Daily Log'!$B$5:$B$4004,A7,'Daily Log'!$A$5:$A$4004,">="&Settings!$B$5,'Daily Log'!$A$5:$A$4004,"<="&Settings!$B$6,'Daily Log'!$M$5:$M$4004,"Yes")) -> 0 | N7: =IF(OR(A7="",E7=0),"",M7/E7) -> 0 | O7: =IF(OR(A7="",N(J7)=0),"",COUNTIF($J$6:$J$65,">"&J7)+1)
A8: =IF('Cashier Roster'!B7="","",'Cashier Roster'!B7) -> Taiwo Noimot | B8: =IF(A8="","",'Cashier Roster'!C7) -> Ajah | C8: =IF(A8="","",'Cashier Roster'!D7) -> District cashier | D8: =IF(A8="","",'Cashier Roster'!H7) -> Active | E8: =IF(A8="","",COUNTIFS('Daily Log'!$B$5:$B$4004,A8,'Daily Log'!$A$5:$A$4004,">="&Settings!$B$5,'Daily Log'!$A$5:$A$4004,"<="&Settings!$B$6)) -> 1 | F8: =IF(A8="","",COUNTIFS('Daily Log'!$B$5:$B$4004,A8,'Daily Log'!$A$5:$A$4004,">="&Settings!$B$5,'Daily Log'!$A$5:$A$4004,"<="&Settings!$B$6,'Daily Log'!$E$5:$E$4004,"Yes")) -> 0 | G8: =IF(A8="","",COUNTIFS('Daily Log'!$B$5:$B$4004,A8,'Daily Log'!$A$5:$A$4004,">="&Settings!$B$5,'Daily Log'!$A$5:$A$4004,"<="&Settings!$B$6,'Daily Log'!$G$5:$G$4004,"On time")) -> 0 | H8: =IF(OR(A8="",E8=0),"",G8/E8) -> 0 | I8: =IF(A8="","",SUMIFS('Daily Log'!$H$5:$H$4004,'Daily Log'!$B$5:$B$4004,A8,'Daily Log'!$A$5:$A$4004,">="&Settings!$B$5,'Daily Log'!$A$5:$A$4004,"<="&Settings!$B$6,'Daily Log'!$E$5:$E$4004,"Yes")) -> 0 | J8: =IF(A8="","",SUMIFS('Daily Log'!$I$5:$I$4004,'Daily Log'!$B$5:$B$4004,A8,'Daily Log'!$A$5:$A$4004,">="&Settings!$B$5,'Daily Log'!$A$5:$A$4004,"<="&Settings!$B$6,'Daily Log'!$E$5:$E$4004,"Yes")) -> 0 | K8: =IF(A8="","",SUMIFS('Daily Log'!$J$5:$J$4004,'Daily Log'!$B$5:$B$4004,A8,'Daily Log'!$A$5:$A$4004,">="&Settings!$B$5,'Daily Log'!$A$5:$A$4004,"<="&Settings!$B$6,'Daily Log'!$E$5:$E$4004,"Yes")) -> 0 | L8: =IF(A8="","",SUMIFS('Daily Log'!$K$5:$K$4004,'Daily Log'!$B$5:$B$4004,A8,'Daily Log'!$A$5:$A$4004,">="&Settings!$B$5,'Daily Log'!$A$5:$A$4004,"<="&Settings!$B$6,'Daily Log'!$E$5:$E$4004,"Yes")) -> 0 | M8: =IF(A8="","",COUNTIFS('Daily Log'!$B$5:$B$4004,A8,'Daily Log'!$A$5:$A$4004,">="&Settings!$B$5,'Daily Log'!$A$5:$A$4004,"<="&Settings!$B$6,'Daily Log'!$M$5:$M$4004,"Yes")) -> 0 | N8: =IF(OR(A8="",E8=0),"",M8/E8) -> 0 | O8: =IF(OR(A8="",N(J8)=0),"",COUNTIF($J$6:$J$65,">"&J8)+1)
A9: =IF('Cashier Roster'!B8="","",'Cashier Roster'!B8) -> Taiwo Akintoye | B9: =IF(A9="","",'Cashier Roster'!C8) -> Ajele | C9: =IF(A9="","",'Cashier Roster'!D8) -> District cashier | D9: =IF(A9="","",'Cashier Roster'!H8) -> Active | E9: =IF(A9="","",COUNTIFS('Daily Log'!$B$5:$B$4004,A9,'Daily Log'!$A$5:$A$4004,">="&Settings!$B$5,'Daily Log'!$A$5:$A$4004,"<="&Settings!$B$6)) -> 1 | F9: =IF(A9="","",COUNTIFS('Daily Log'!$B$5:$B$4004,A9,'Daily Log'!$A$5:$A$4004,">="&Settings!$B$5,'Daily Log'!$A$5:$A$4004,"<="&Settings!$B$6,'Daily Log'!$E$5:$E$4004,"Yes")) -> 0 | G9: =IF(A9="","",COUNTIFS('Daily Log'!$B$5:$B$4004,A9,'Daily Log'!$A$5:$A$4004,">="&Settings!$B$5,'Daily Log'!$A$5:$A$4004,"<="&Settings!$B$6,'Daily Log'!$G$5:$G$4004,"On time")) -> 0 | H9: =IF(OR(A9="",E9=0),"",G9/E9) -> 0 | I9: =IF(A9="","",SUMIFS('Daily Log'!$H$5:$H$4004,'Daily Log'!$B$5:$B$4004,A9,'Daily Log'!$A$5:$A$4004,">="&Settings!$B$5,'Daily Log'!$A$5:$A$4004,"<="&Settings!$B$6,'Daily Log'!$E$5:$E$4004,"Yes")) -> 0 | J9: =IF(A9="","",SUMIFS('Daily Log'!$I$5:$I$4004,'Daily Log'!$B$5:$B$4004,A9,'Daily Log'!$A$5:$A$4004,">="&Settings!$B$5,'Daily Log'!$A$5:$A$4004,"<="&Settings!$B$6,'Daily Log'!$E$5:$E$4004,"Yes")) -> 0 | K9: =IF(A9="","",SUMIFS('Daily Log'!$J$5:$J$4004,'Daily Log'!$B$5:$B$4004,A9,'Daily Log'!$A$5:$A$4004,">="&Settings!$B$5,'Daily Log'!$A$5:$A$4004,"<="&Settings!$B$6,'Daily Log'!$E$5:$E$4004,"Yes")) -> 0 | L9: =IF(A9="","",SUMIFS('Daily Log'!$K$5:$K$4004,'Daily Log'!$B$5:$B$4004,A9,'Daily Log'!$A$5:$A$4004,">="&Settings!$B$5,'Daily Log'!$A$5:$A$4004,"<="&Settings!$B$6,'Daily Log'!$E$5:$E$4004,"Yes")) -> 0 | M9: =IF(A9="","",COUNTIFS('Daily Log'!$B$5:$B$4004,A9,'Daily Log'!$A$5:$A$4004,">="&Settings!$B$5,'Daily Log'!$A$5:$A$4004,"<="&Settings!$B$6,'Daily Log'!$M$5:$M$4004,"Yes")) -> 0 | N9: =IF(OR(A9="",E9=0),"",M9/E9) -> 0 | O9: =IF(OR(A9="",N(J9)=0),"",COUNTIF($J$6:$J$65,">"&J9)+1)
A10: =IF('Cashier Roster'!B9="","",'Cashier Roster'!B9) -> Mary Agbim | B10: =IF(A10="","",'Cashier Roster'!C9) -> Ajele | C10: =IF(A10="","",'Cashier Roster'!D9) -> Zone cashier (new) | D10: =IF(A10="","",'Cashier Roster'!H9) -> Active | E10: =IF(A10="","",COUNTIFS('Daily Log'!$B$5:$B$4004,A10,'Daily Log'!$A$5:$A$4004,">="&Settings!$B$5,'Daily Log'!$A$5:$A$4004,"<="&Settings!$B$6)) -> 1 | F10: =IF(A10="","",COUNTIFS('Daily Log'!$B$5:$B$4004,A10,'Daily Log'!$A$5:$A$4004,">="&Settings!$B$5,'Daily Log'!$A$5:$A$4004,"<="&Settings!$B$6,'Daily Log'!$E$5:$E$4004,"Yes")) -> 0 | G10: =IF(A10="","",COUNTIFS('Daily Log'!$B$5:$B$4004,A10,'Daily Log'!$A$5:$A$4004,">="&Settings!$B$5,'Daily Log'!$A$5:$A$4004,"<="&Settings!$B$6,'Daily Log'!$G$5:$G$4004,"On time")) -> 0 | H10: =IF(OR(A10="",E10=0),"",G10/E10) -> 0 | I10: =IF(A10="","",SUMIFS('Daily Log'!$H$5:$H$4004,'Daily Log'!$B$5:$B$4004,A10,'Daily Log'!$A$5:$A$4004,">="&Settings!$B$5,'Daily Log'!$A$5:$A$4004,"<="&Settings!$B$6,'Daily Log'!$E$5:$E$4004,"Yes")) -> 0 | J10: =IF(A10="","",SUMIFS('Daily Log'!$I$5:$I$4004,'Daily Log'!$B$5:$B$4004,A10,'Daily Log'!$A$5:$A$4004,">="&Settings!$B$5,'Daily Log'!$A$5:$A$4004,"<="&Settings!$B$6,'Daily Log'!$E$5:$E$4004,"Yes")) -> 0 | K10: =IF(A10="","",SUMIFS('Daily Log'!$J$5:$J$4004,'Daily Log'!$B$5:$B$4004,A10,'Daily Log'!$A$5:$A$4004,">="&Settings!$B$5,'Daily Log'!$A$5:$A$4004,"<="&Settings!$B$6,'Daily Log'!$E$5:$E$4004,"Yes")) -> 0 | L10: =IF(A10="","",SUMIFS('Daily Log'!$K$5:$K$4004,'Daily Log'!$B$5:$B$4004,A10,'Daily Log'!$A$5:$A$4004,">="&Settings!$B$5,'Daily Log'!$A$5:$A$4004,"<="&Settings!$B$6,'Daily Log'!$E$5:$E$4004,"Yes")) -> 0 | M10: =IF(A10="","",COUNTIFS('Daily Log'!$B$5:$B$4004,A10,'Daily Log'!$A$5:$A$4004,">="&Settings!$B$5,'Daily Log'!$A$5:$A$4004,"<="&Settings!$B$6,'Daily Log'!$M$5:$M$4004,"Yes")) -> 0 | N10: =IF(OR(A10="",E10=0),"",M10/E10) -> 0 | O10: =IF(OR(A10="",N(J10)=0),"",COUNTIF($J$6:$J$65,">"&J10)+1)
A11: =IF('Cashier Roster'!B10="","",'Cashier Roster'!B10) -> Ojulari Waheed | B11: =IF(A11="","",'Cashier Roster'!C10) -> Apapa | C11: =IF(A11="","",'Cashier Roster'!D10) -> District cashier | D11: =IF(A11="","",'Cashier Roster'!H10) -> Active | E11: =IF(A11="","",COUNTIFS('Daily Log'!$B$5:$B$4004,A11,'Daily Log'!$A$5:$A$4004,">="&Settings!$B$5,'Daily Log'!$A$5:$A$4004,"<="&Settings!$B$6)) -> 1 | F11: =IF(A11="","",COUNTIFS('Daily Log'!$B$5:$B$4004,A11,'Daily Log'!$A$5:$A$4004,">="&Settings!$B$5,'Daily Log'!$A$5:$A$4004,"<="&Settings!$B$6,'Daily Log'!$E$5:$E$4004,"Yes")) -> 0 | G11: =IF(A11="","",COUNTIFS('Daily Log'!$B$5:$B$4004,A11,'Daily Log'!$A$5:$A$4004,">="&Settings!$B$5,'Daily Log'!$A$5:$A$4004,"<="&Settings!$B$6,'Daily Log'!$G$5:$G$4004,"On time")) -> 0 | H11: =IF(OR(A11="",E11=0),"",G11/E11) -> 0 | I11: =IF(A11="","",SUMIFS('Daily Log'!$H$5:$H$4004,'Daily Log'!$B$5:$B$4004,A11,'Daily Log'!$A$5:$A$4004,">="&Settings!$B$5,'Daily Log'!$A$5:$A$4004,"<="&Settings!$B$6,'Daily Log'!$E$5:$E$4004,"Yes")) -> 0 | J11: =IF(A11="","",SUMIFS('Daily Log'!$I$5:$I$4004,'Daily Log'!$B$5:$B$4004,A11,'Daily Log'!$A$5:$A$4004,">="&Settings!$B$5,'Daily Log'!$A$5:$A$4004,"<="&Settings!$B$6,'Daily Log'!$E$5:$E$4004,"Yes")) -> 0 | K11: =IF(A11="","",SUMIFS('Daily Log'!$J$5:$J$4004,'Daily Log'!$B$5:$B$4004,A11,'Daily Log'!$A$5:$A$4004,">="&Settings!$B$5,'Daily Log'!$A$5:$A$4004,"<="&Settings!$B$6,'Daily Log'!$E$5:$E$4004,"Yes")) -> 0 | L11: =IF(A11="","",SUMIFS('Daily Log'!$K$5:$K$4004,'Daily Log'!$B$5:$B$4004,A11,'Daily Log'!$A$5:$A$4004,">="&Settings!$B$5,'Daily Log'!$A$5:$A$4004,"<="&Settings!$B$6,'Daily Log'!$E$5:$E$4004,"Yes")) -> 0 | M11: =IF(A11="","",COUNTIFS('Daily Log'!$B$5:$B$4004,A11,'Daily Log'!$A$5:$A$4004,">="&Settings!$B$5,'Daily Log'!$A$5:$A$4004,"<="&Settings!$B$6,'Daily Log'!$M$5:$M$4004,"Yes")) -> 0 | N11: =IF(OR(A11="",E11=0),"",M11/E11) -> 0 | O11: =IF(OR(A11="",N(J11)=0),"",COUNTIF($J$6:$J$65,">"&J11)+1)
A12: =IF('Cashier Roster'!B11="","",'Cashier Roster'!B11) -> Ikudehinbo Oluwatosin | B12: =IF(A12="","",'Cashier Roster'!C11) -> Apapa | C12: =IF(A12="","",'Cashier Roster'!D11) -> Zone cashier (new) | D12: =IF(A12="","",'Cashier Roster'!H11) -> Active | E12: =IF(A12="","",COUNTIFS('Daily Log'!$B$5:$B$4004,A12,'Daily Log'!$A$5:$A$4004,">="&Settings!$B$5,'Daily Log'!$A$5:$A$4004,"<="&Settings!$B$6)) -> 1 | F12: =IF(A12="","",COUNTIFS('Daily Log'!$B$5:$B$4004,A12,'Daily Log'!$A$5:$A$4004,">="&Settings!$B$5,'Daily Log'!$A$5:$A$4004,"<="&Settings!$B$6,'Daily Log'!$E$5:$E$4004,"Yes")) -> 0 | G12: =IF(A12="","",COUNTIFS('Daily Log'!$B$5:$B$4004,A12,'Daily Log'!$A$5:$A$4004,">="&Settings!$B$5,'Daily Log'!$A$5:$A$4004,"<="&Settings!$B$6,'Daily Log'!$G$5:$G$4004,"On time")) -> 0 | H12: =IF(OR(A12="",E12=0),"",G12/E12) -> 0 | I12: =IF(A12="","",SUMIFS('Daily Log'!$H$5:$H$4004,'Daily Log'!$B$5:$B$4004,A12,'Daily Log'!$A$5:$A$4004,">="&Settings!$B$5,'Daily Log'!$A$5:$A$4004,"<="&Settings!$B$6,'Daily Log'!$E$5:$E$4004,"Yes")) -> 0 | J12: =IF(A12="","",SUMIFS('Daily Log'!$I$5:$I$4004,'Daily Log'!$B$5:$B$4004,A12,'Daily Log'!$A$5:$A$4004,">="&Settings!$B$5,'Daily Log'!$A$5:$A$4004,"<="&Settings!$B$6,'Daily Log'!$E$5:$E$4004,"Yes")) -> 0 | K12: =IF(A12="","",SUMIFS('Daily Log'!$J$5:$J$4004,'Daily Log'!$B$5:$B$4004,A12,'Daily Log'!$A$5:$A$4004,">="&Settings!$B$5,'Daily Log'!$A$5:$A$4004,"<="&Settings!$B$6,'Daily Log'!$E$5:$E$4004,"Yes")) -> 0 | L12: =IF(A12="","",SUMIFS('Daily Log'!$K$5:$K$4004,'Daily Log'!$B$5:$B$4004,A12,'Daily Log'!$A$5:$A$4004,">="&Settings!$B$5,'Daily Log'!$A$5:$A$4004,"<="&Settings!$B$6,'Daily Log'!$E$5:$E$4004,"Yes")) -> 0 | M12: =IF(A12="","",COUNTIFS('Daily Log'!$B$5:$B$4004,A12,'Daily Log'!$A$5:$A$4004,">="&Settings!$B$5,'Daily Log'!$A$5:$A$4004,"<="&Settings!$B$6,'Daily Log'!$M$5:$M$4004,"Yes")) -> 0 | N12: =IF(OR(A12="",E12=0),"",M12/E12) -> 0 | O12: =IF(OR(A12="",N(J12)=0),"",COUNTIF($J$6:$J$65,">"&J12)+1)
A13: =IF('Cashier Roster'!B12="","",'Cashier Roster'!B12) -> Onileowo Victoria | B13: =IF(A13="","",'Cashier Roster'!C12) -> Festac | C13: =IF(A13="","",'Cashier Roster'!D12) -> District cashier | D13: =IF(A13="","",'Cashier Roster'!H12) -> Active | E13: =IF(A13="","",COUNTIFS('Daily Log'!$B$5:$B$4004,A13,'Daily Log'!$A$5:$A$4004,">="&Settings!$B$5,'Daily Log'!$A$5:$A$4004,"<="&Settings!$B$6)) -> 1 | F13: =IF(A13="","",COUNTIFS('Daily Log'!$B$5:$B$4004,A13,'Daily Log'!$A$5:$A$4004,">="&Settings!$B$5,'Daily Log'!$A$5:$A$4004,"<="&Settings!$B$6,'Daily Log'!$E$5:$E$4004,"Yes")) -> 0 | G13: =IF(A13="","",COUNTIFS('Daily Log'!$B$5:$B$4004,A13,'Daily Log'!$A$5:$A$4004,">="&Settings!$B$5,'Daily Log'!$A$5:$A$4004,"<="&Settings!$B$6,'Daily Log'!$G$5:$G$4004,"On time")) -> 0 | H13: =IF(OR(A13="",E13=0),"",G13/E13) -> 0 | I13: =IF(A13="","",SUMIFS('Daily Log'!$H$5:$H$4004,'Daily Log'!$B$5:$B$4004,A13,'Daily Log'!$A$5:$A$4004,">="&Settings!$B$5,'Daily Log'!$A$5:$A$4004,"<="&Settings!$B$6,'Daily Log'!$E$5:$E$4004,"Yes")) -> 0 | J13: =IF(A13="","",SUMIFS('Daily Log'!$I$5:$I$4004,'Daily Log'!$B$5:$B$4004,A13,'Daily Log'!$A$5:$A$4004,">="&Settings!$B$5,'Daily Log'!$A$5:$A$4004,"<="&Settings!$B$6,'Daily Log'!$E$5:$E$4004,"Yes")) -> 0 | K13: =IF(A13="","",SUMIFS('Daily Log'!$J$5:$J$4004,'Daily Log'!$B$5:$B$4004,A13,'Daily Log'!$A$5:$A$4004,">="&Settings!$B$5,'Daily Log'!$A$5:$A$4004,"<="&Settings!$B$6,'Daily Log'!$E$5:$E$4004,"Yes")) -> 0 | L13: =IF(A13="","",SUMIFS('Daily Log'!$K$5:$K$4004,'Daily Log'!$B$5:$B$4004,A13,'Daily Log'!$A$5:$A$4004,">="&Settings!$B$5,'Daily Log'!$A$5:$A$4004,"<="&Settings!$B$6,'Daily Log'!$E$5:$E$4004,"Yes")) -> 0 | M13: =IF(A13="","",COUNTIFS('Daily Log'!$B$5:$B$4004,A13,'Daily Log'!$A$5:$A$4004,">="&Settings!$B$5,'Daily Log'!$A$5:$A$4004,"<="&Settings!$B$6,'Daily Log'!$M$5:$M$4004,"Yes")) -> 0 | N13: =IF(OR(A13="",E13=0),"",M13/E13) -> 0 | O13: =IF(OR(A13="",N(J13)=0),"",COUNTIF($J$6:$J$65,">"&J13)+1)
A14: =IF('Cashier Roster'!B13="","",'Cashier Roster'!B13) -> Oluwaseyi Ajayi | B14: =IF(A14="","",'Cashier Roster'!C13) -> Festac | C14: =IF(A14="","",'Cashier Roster'!D13) -> Zone cashier (new) | D14: =IF(A14="","",'Cashier Roster'!H13) -> Active | E14: =IF(A14="","",COUNTIFS('Daily Log'!$B$5:$B$4004,A14,'Daily Log'!$A$5:$A$4004,">="&Settings!$B$5,'Daily Log'!$A$5:$A$4004,"<="&Settings!$B$6)) -> 1 | F14: =IF(A14="","",COUNTIFS('Daily Log'!$B$5:$B$4004,A14,'Daily Log'!$A$5:$A$4004,">="&Settings!$B$5,'Daily Log'!$A$5:$A$4004,"<="&Settings!$B$6,'Daily Log'!$E$5:$E$4004,"Yes")) -> 0 | G14: =IF(A14="","",COUNTIFS('Daily Log'!$B$5:$B$4004,A14,'Daily Log'!$A$5:$A$4004,">="&Settings!$B$5,'Daily Log'!$A$5:$A$4004,"<="&Settings!$B$6,'Daily Log'!$G$5:$G$4004,"On time")) -> 0 | H14: =IF(OR(A14="",E14=0),"",G14/E14) -> 0 | I14: =IF(A14="","",SUMIFS('Daily Log'!$H$5:$H$4004,'Daily Log'!$B$5:$B$4004,A14,'Daily Log'!$A$5:$A$4004,">="&Settings!$B$5,'Daily Log'!$A$5:$A$4004,"<="&Settings!$B$6,'Daily Log'!$E$5:$E$4004,"Yes")) -> 0 | J14: =IF(A14="","",SUMIFS('Daily Log'!$I$5:$I$4004,'Daily Log'!$B$5:$B$4004,A14,'Daily Log'!$A$5:$A$4004,">="&Settings!$B$5,'Daily Log'!$A$5:$A$4004,"<="&Settings!$B$6,'Daily Log'!$E$5:$E$4004,"Yes")) -> 0 | K14: =IF(A14="","",SUMIFS('Daily Log'!$J$5:$J$4004,'Daily Log'!$B$5:$B$4004,A14,'Daily Log'!$A$5:$A$4004,">="&Settings!$B$5,'Daily Log'!$A$5:$A$4004,"<="&Settings!$B$6,'Daily Log'!$E$5:$E$4004,"Yes")) -> 0 | L14: =IF(A14="","",SUMIFS('Daily Log'!$K$5:$K$4004,'Daily Log'!$B$5:$B$4004,A14,'Daily Log'!$A$5:$A$4004,">="&Settings!$B$5,'Daily Log'!$A$5:$A$4004,"<="&Settings!$B$6,'Daily Log'!$E$5:$E$4004,"Yes")) -> 0 | M14: =IF(A14="","",COUNTIFS('Daily Log'!$B$5:$B$4004,A14,'Daily Log'!$A$5:$A$4004,">="&Settings!$B$5,'Daily Log'!$A$5:$A$4004,"<="&Settings!$B$6,'Daily Log'!$M$5:$M$4004,"Yes")) -> 0 | N14: =IF(OR(A14="",E14=0),"",M14/E14) -> 0 | O14: =IF(OR(A14="",N(J14)=0),"",COUNTIF($J$6:$J$65,">"&J14)+1)
A15: =IF('Cashier Roster'!B14="","",'Cashier Roster'!B14) -> Okiji Olubunmi Jacob | B15: =IF(A15="","",'Cashier Roster'!C14) -> Ibeju | C15: =IF(A15="","",'Cashier Roster'!D14) -> District cashier | D15: =IF(A15="","",'Cashier Roster'!H14) -> Active | E15: =IF(A15="","",COUNTIFS('Daily Log'!$B$5:$B$4004,A15,'Daily Log'!$A$5:$A$4004,">="&Settings!$B$5,'Daily Log'!$A$5:$A$4004,"<="&Settings!$B$6)) -> 1 | F15: =IF(A15="","",COUNTIFS('Daily Log'!$B$5:$B$4004,A15,'Daily Log'!$A$5:$A$4004,">="&Settings!$B$5,'Daily Log'!$A$5:$A$4004,"<="&Settings!$B$6,'Daily Log'!$E$5:$E$4004,"Yes")) -> 0 | G15: =IF(A15="","",COUNTIFS('Daily Log'!$B$5:$B$4004,A15,'Daily Log'!$A$5:$A$4004,">="&Settings!$B$5,'Daily Log'!$A$5:$A$4004,"<="&Settings!$B$6,'Daily Log'!$G$5:$G$4004,"On time")) -> 0 | H15: =IF(OR(A15="",E15=0),"",G15/E15) -> 0 | I15: =IF(A15="","",SUMIFS('Daily Log'!$H$5:$H$4004,'Daily Log'!$B$5:$B$4004,A15,'Daily Log'!$A$5:$A$4004,">="&Settings!$B$5,'Daily Log'!$A$5:$A$4004,"<="&Settings!$B$6,'Daily Log'!$E$5:$E$4004,"Yes")) -> 0 | J15: =IF(A15="","",SUMIFS('Daily Log'!$I$5:$I$4004,'Daily Log'!$B$5:$B$4004,A15,'Daily Log'!$A$5:$A$4004,">="&Settings!$B$5,'Daily Log'!$A$5:$A$4004,"<="&Settings!$B$6,'Daily Log'!$E$5:$E$4004,"Yes")) -> 0 | K15: =IF(A15="","",SUMIFS('Daily Log'!$J$5:$J$4004,'Daily Log'!$B$5:$B$4004,A15,'Daily Log'!$A$5:$A$4004,">="&Settings!$B$5,'Daily Log'!$A$5:$A$4004,"<="&Settings!$B$6,'Daily Log'!$E$5:$E$4004,"Yes")) -> 0 | L15: =IF(A15="","",SUMIFS('Daily Log'!$K$5:$K$4004,'Daily Log'!$B$5:$B$4004,A15,'Daily Log'!$A$5:$A$4004,">="&Settings!$B$5,'Daily Log'!$A$5:$A$4004,"<="&Settings!$B$6,'Daily Log'!$E$5:$E$4004,"Yes")) -> 0 | M15: =IF(A15="","",COUNTIFS('Daily Log'!$B$5:$B$4004,A15,'Daily Log'!$A$5:$A$4004,">="&Settings!$B$5,'Daily Log'!$A$5:$A$4004,"<="&Settings!$B$6,'Daily Log'!$M$5:$M$4004,"Yes")) -> 0 | N15: =IF(OR(A15="",E15=0),"",M15/E15) -> 0 | O15: =IF(OR(A15="",N(J15)=0),"",COUNTIF($J$6:$J$65,">"&J15)+1)
A16: =IF('Cashier Roster'!B15="","",'Cashier Roster'!B15) -> Adebari Temitayo | B16: =IF(A16="","",'Cashier Roster'!C15) -> Ijora | C16: =IF(A16="","",'Cashier Roster'!D15) -> District cashier | D16: =IF(A16="","",'Cashier Roster'!H15) -> Active | E16: =IF(A16="","",COUNTIFS('Daily Log'!$B$5:$B$4004,A16,'Daily Log'!$A$5:$A$4004,">="&Settings!$B$5,'Daily Log'!$A$5:$A$4004,"<="&Settings!$B$6)) -> 1 | F16: =IF(A16="","",COUNTIFS('Daily Log'!$B$5:$B$4004,A16,'Daily Log'!$A$5:$A$4004,">="&Settings!$B$5,'Daily Log'!$A$5:$A$4004,"<="&Settings!$B$6,'Daily Log'!$E$5:$E$4004,"Yes")) -> 0 | G16: =IF(A16="","",COUNTIFS('Daily Log'!$B$5:$B$4004,A16,'Daily Log'!$A$5:$A$4004,">="&Settings!$B$5,'Daily Log'!$A$5:$A$4004,"<="&Settings!$B$6,'Daily Log'!$G$5:$G$4004,"On time")) -> 0 | H16: =IF(OR(A16="",E16=0),"",G16/E16) -> 0 | I16: =IF(A16="","",SUMIFS('Daily Log'!$H$5:$H$4004,'Daily Log'!$B$5:$B$4004,A16,'Daily Log'!$A$5:$A$4004,">="&Settings!$B$5,'Daily Log'!$A$5:$A$4004,"<="&Settings!$B$6,'Daily Log'!$E$5:$E$4004,"Yes")) -> 0 | J16: =IF(A16="","",SUMIFS('Daily Log'!$I$5:$I$4004,'Daily Log'!$B$5:$B$4004,A16,'Daily Log'!$A$5:$A$4004,">="&Settings!$B$5,'Daily Log'!$A$5:$A$4004,"<="&Settings!$B$6,'Daily Log'!$E$5:$E$4004,"Yes")) -> 0 | K16: =IF(A16="","",SUMIFS('Daily Log'!$J$5:$J$4004,'Daily Log'!$B$5:$B$4004,A16,'Daily Log'!$A$5:$A$4004,">="&Settings!$B$5,'Daily Log'!$A$5:$A$4004,"<="&Settings!$B$6,'Daily Log'!$E$5:$E$4004,"Yes")) -> 0 | L16: =IF(A16="","",SUMIFS('Daily Log'!$K$5:$K$4004,'Daily Log'!$B$5:$B$4004,A16,'Daily Log'!$A$5:$A$4004,">="&Settings!$B$5,'Daily Log'!$A$5:$A$4004,"<="&Settings!$B$6,'Daily Log'!$E$5:$E$4004,"Yes")) -> 0 | M16: =IF(A16="","",COUNTIFS('Daily Log'!$B$5:$B$4004,A16,'Daily Log'!$A$5:$A$4004,">="&Settings!$B$5,'Daily Log'!$A$5:$A$4004,"<="&Settings!$B$6,'Daily Log'!$M$5:$M$4004,"Yes")) -> 0 | N16: =IF(OR(A16="",E16=0),"",M16/E16) -> 0 | O16: =IF(OR(A16="",N(J16)=0),"",COUNTIF($J$6:$J$65,">"&J16)+1)
A17: =IF('Cashier Roster'!B16="","",'Cashier Roster'!B16) -> Ibeto Catherine | B17: =IF(A17="","",'Cashier Roster'!C16) -> Ijora | C17: =IF(A17="","",'Cashier Roster'!D16) -> Zone cashier (new) | D17: =IF(A17="","",'Cashier Roster'!H16) -> Active | E17: =IF(A17="","",COUNTIFS('Daily Log'!$B$5:$B$4004,A17,'Daily Log'!$A$5:$A$4004,">="&Settings!$B$5,'Daily Log'!$A$5:$A$4004,"<="&Settings!$B$6)) -> 1 | F17: =IF(A17="","",COUNTIFS('Daily Log'!$B$5:$B$4004,A17,'Daily Log'!$A$5:$A$4004,">="&Settings!$B$5,'Daily Log'!$A$5:$A$4004,"<="&Settings!$B$6,'Daily Log'!$E$5:$E$4004,"Yes")) -> 0 | G17: =IF(A17="","",COUNTIFS('Daily Log'!$B$5:$B$4004,A17,'Daily Log'!$A$5:$A$4004,">="&Settings!$B$5,'Daily Log'!$A$5:$A$4004,"<="&Settings!$B$6,'Daily Log'!$G$5:$G$4004,"On time")) -> 0 | H17: =IF(OR(A17="",E17=0),"",G17/E17) -> 0 | I17: =IF(A17="","",SUMIFS('Daily Log'!$H$5:$H$4004,'Daily Log'!$B$5:$B$4004,A17,'Daily Log'!$A$5:$A$4004,">="&Settings!$B$5,'Daily Log'!$A$5:$A$4004,"<="&Settings!$B$6,'Daily Log'!$E$5:$E$4004,"Yes")) -> 0 | J17: =IF(A17="","",SUMIFS('Daily Log'!$I$5:$I$4004,'Daily Log'!$B$5:$B$4004,A17,'Daily Log'!$A$5:$A$4004,">="&Settings!$B$5,'Daily Log'!$A$5:$A$4004,"<="&Settings!$B$6,'Daily Log'!$E$5:$E$4004,"Yes")) -> 0 | K17: =IF(A17="","",SUMIFS('Daily Log'!$J$5:$J$4004,'Daily Log'!$B$5:$B$4004,A17,'Daily Log'!$A$5:$A$4004,">="&Settings!$B$5,'Daily Log'!$A$5:$A$4004,"<="&Settings!$B$6,'Daily Log'!$E$5:$E$4004,"Yes")) -> 0 | L17: =IF(A17="","",SUMIFS('Daily Log'!$K$5:$K$4004,'Daily Log'!$B$5:$B$4004,A17,'Daily Log'!$A$5:$A$4004,">="&Settings!$B$5,'Daily Log'!$A$5:$A$4004,"<="&Settings!$B$6,'Daily Log'!$E$5:$E$4004,"Yes")) -> 0 | M17: =IF(A17="","",COUNTIFS('Daily Log'!$B$5:$B$4004,A17,'Daily Log'!$A$5:$A$4004,">="&Settings!$B$5,'Daily Log'!$A$5:$A$4004,"<="&Settings!$B$6,'Daily Log'!$M$5:$M$4004,"Yes")) -> 0 | N17: =IF(OR(A17="",E17=0),"",M17/E17) -> 0 | O17: =IF(OR(A17="",N(J17)=0),"",COUNTIF($J$6:$J$65,">"&J17)+1)
... A65: =IF('Cashier Roster'!B64="","",'Cashier Roster'!B64) | B65: =IF(A65="","",'Cashier Roster'!C64) | C65: =IF(A65="","",'Cashier Roster'!D64) | D65: =IF(A65="","",'Cashier Roster'!H64) | E65: =IF(A65="","",COUNTIFS('Daily Log'!$B$5:$B$4004,A65,'Daily Log'!$A$5:$A$4004,">="&Settings!$B$5,'Daily Log'!$A$5:$A$4004,"<="&Settings!$B$6)) | F65: =IF(A65="","",COUNTIFS('Daily Log'!$B$5:$B$4004,A65,'Daily Log'!$A$5:$A$4004,">="&Settings!$B$5,'Daily Log'!$A$5:$A$4004,"<="&Settings!$B$6,'Daily Log'!$E$5:$E$4004,"Yes")) | G65: =IF(A65="","",COUNTIFS('Daily Log'!$B$5:$B$4004,A65,'Daily Log'!$A$5:$A$4004,">="&Settings!$B$5,'Daily Log'!$A$5:$A$4004,"<="&Settings!$B$6,'Daily Log'!$G$5:$G$4004,"On time")) | H65: =IF(OR(A65="",E65=0),"",G65/E65) | I65: =IF(A65="","",SUMIFS('Daily Log'!$H$5:$H$4004,'Daily Log'!$B$5:$B$4004,A65,'Daily Log'!$A$5:$A$4004,">="&Settings!$B$5,'Daily Log'!$A$5:$A$4004,"<="&Settings!$B$6,'Daily Log'!$E$5:$E$4004,"Yes")) | J65: =IF(A65="","",SUMIFS('Daily Log'!$I$5:$I$4004,'Daily Log'!$B$5:$B$4004,A65,'Daily Log'!$A$5:$A$4004,">="&Settings!$B$5,'Daily Log'!$A$5:$A$4004,"<="&Settings!$B$6,'Daily Log'!$E$5:$E$4004,"Yes")) | K65: =IF(A65="","",SUMIFS('Daily Log'!$J$5:$J$4004,'Daily Log'!$B$5:$B$4004,A65,'Daily Log'!$A$5:$A$4004,">="&Settings!$B$5,'Daily Log'!$A$5:$A$4004,"<="&Settings!$B$6,'Daily Log'!$E$5:$E$4004,"Yes")) | L65: =IF(A65="","",SUMIFS('Daily Log'!$K$5:$K$4004,'Daily Log'!$B$5:$B$4004,A65,'Daily Log'!$A$5:$A$4004,">="&Settings!$B$5,'Daily Log'!$A$5:$A$4004,"<="&Settings!$B$6,'Daily Log'!$E$5:$E$4004,"Yes")) | M65: =IF(A65="","",COUNTIFS('Daily Log'!$B$5:$B$4004,A65,'Daily Log'!$A$5:$A$4004,">="&Settings!$B$5,'Daily Log'!$A$5:$A$4004,"<="&Settings!$B$6,'Daily Log'!$M$5:$M$4004,"Yes")) | N65: =IF(OR(A65="",E65=0),"",M65/E65) | O65: =IF(OR(A65="",N(J65)=0),"",COUNTIF($J$6:$J$65,">"&J65)+1)
A67: Red: on-time or zeroization rate below 80%. Gold: top three collectors.

Sheet District Summary
A1: District Summary
A2: Cashier collections by district for the period on the Settings tab. Enter a cashier target per district to track attainment (optional).
A3: =" Period: "&TEXT(Settings!$B$5,"dd/mm/yyyy")&" to "&TEXT(Settings!$B$6,"dd/mm/yyyy") -> Period: 01/10/2026 to 31/10/2026
A5: District | B5: Active Cashiers | C5: of which Zone (new) | D5: Reports Expected* | E5: Reports Received | F5: Reporting Rate | G5: Transactions | H5: Total Collected (₦) | I5: NKCG (₦) | J5: Commission (₦) | K5: Avg per Cashier (₦) | L5: Cashier Target (₦) | M5: % of Target
A6: Agbara | B6: =COUNTIFS('Cashier Roster'!$C$5:$C$64,A6,'Cashier Roster'!$H$5:$H$64,"Active") -> 2 | C6: =COUNTIFS('Cashier Roster'!$C$5:$C$64,A6,'Cashier Roster'!$H$5:$H$64,"Active",'Cashier Roster'!$D$5:$D$64,"Zone cashier (new)") -> 1 | D6: =COUNTIFS('Daily Log'!$C$5:$C$4004,A6,'Daily Log'!$A$5:$A$4004,">="&Settings!$B$5,'Daily Log'!$A$5:$A$4004,"<="&Settings!$B$6) -> 2 | E6: =COUNTIFS('Daily Log'!$C$5:$C$4004,A6,'Daily Log'!$A$5:$A$4004,">="&Settings!$B$5,'Daily Log'!$A$5:$A$4004,"<="&Settings!$B$6,'Daily Log'!$E$5:$E$4004,"Yes") -> 0 | F6: =IF(D6=0,"",E6/D6) -> 0 | G6: =SUMIFS('Daily Log'!$H$5:$H$4004,'Daily Log'!$C$5:$C$4004,A6,'Daily Log'!$A$5:$A$4004,">="&Settings!$B$5,'Daily Log'!$A$5:$A$4004,"<="&Settings!$B$6,'Daily Log'!$E$5:$E$4004,"Yes") -> 0 | H6: =SUMIFS('Daily Log'!$I$5:$I$4004,'Daily Log'!$C$5:$C$4004,A6,'Daily Log'!$A$5:$A$4004,">="&Settings!$B$5,'Daily Log'!$A$5:$A$4004,"<="&Settings!$B$6,'Daily Log'!$E$5:$E$4004,"Yes") -> 0 | I6: =SUMIFS('Daily Log'!$J$5:$J$4004,'Daily Log'!$C$5:$C$4004,A6,'Daily Log'!$A$5:$A$4004,">="&Settings!$B$5,'Daily Log'!$A$5:$A$4004,"<="&Settings!$B$6,'Daily Log'!$E$5:$E$4004,"Yes") -> 0 | J6: =SUMIFS('Daily Log'!$K$5:$K$4004,'Daily Log'!$C$5:$C$4004,A6,'Daily Log'!$A$5:$A$4004,">="&Settings!$B$5,'Daily Log'!$A$5:$A$4004,"<="&Settings!$B$6,'Daily Log'!$E$5:$E$4004,"Yes") -> 0 | K6: =IF(B6=0,"",H6/B6) -> 0 | M6: =IF(N(L6)=0,"",H6/L6)
A7: Ajah | B7: =COUNTIFS('Cashier Roster'!$C$5:$C$64,A7,'Cashier Roster'!$H$5:$H$64,"Active") -> 1 | C7: =COUNTIFS('Cashier Roster'!$C$5:$C$64,A7,'Cashier Roster'!$H$5:$H$64,"Active",'Cashier Roster'!$D$5:$D$64,"Zone cashier (new)") -> 0 | D7: =COUNTIFS('Daily Log'!$C$5:$C$4004,A7,'Daily Log'!$A$5:$A$4004,">="&Settings!$B$5,'Daily Log'!$A$5:$A$4004,"<="&Settings!$B$6) -> 1 | E7: =COUNTIFS('Daily Log'!$C$5:$C$4004,A7,'Daily Log'!$A$5:$A$4004,">="&Settings!$B$5,'Daily Log'!$A$5:$A$4004,"<="&Settings!$B$6,'Daily Log'!$E$5:$E$4004,"Yes") -> 0 | F7: =IF(D7=0,"",E7/D7) -> 0 | G7: =SUMIFS('Daily Log'!$H$5:$H$4004,'Daily Log'!$C$5:$C$4004,A7,'Daily Log'!$A$5:$A$4004,">="&Settings!$B$5,'Daily Log'!$A$5:$A$4004,"<="&Settings!$B$6,'Daily Log'!$E$5:$E$4004,"Yes") -> 0 | H7: =SUMIFS('Daily Log'!$I$5:$I$4004,'Daily Log'!$C$5:$C$4004,A7,'Daily Log'!$A$5:$A$4004,">="&Settings!$B$5,'Daily Log'!$A$5:$A$4004,"<="&Settings!$B$6,'Daily Log'!$E$5:$E$4004,"Yes") -> 0 | I7: =SUMIFS('Daily Log'!$J$5:$J$4004,'Daily Log'!$C$5:$C$4004,A7,'Daily Log'!$A$5:$A$4004,">="&Settings!$B$5,'Daily Log'!$A$5:$A$4004,"<="&Settings!$B$6,'Daily Log'!$E$5:$E$4004,"Yes") -> 0 | J7: =SUMIFS('Daily Log'!$K$5:$K$4004,'Daily Log'!$C$5:$C$4004,A7,'Daily Log'!$A$5:$A$4004,">="&Settings!$B$5,'Daily Log'!$A$5:$A$4004,"<="&Settings!$B$6,'Daily Log'!$E$5:$E$4004,"Yes") -> 0 | K7: =IF(B7=0,"",H7/B7) -> 0 | M7: =IF(N(L7)=0,"",H7/L7)
A8: Ajele | B8: =COUNTIFS('Cashier Roster'!$C$5:$C$64,A8,'Cashier Roster'!$H$5:$H$64,"Active") -> 2 | C8: =COUNTIFS('Cashier Roster'!$C$5:$C$64,A8,'Cashier Roster'!$H$5:$H$64,"Active",'Cashier Roster'!$D$5:$D$64,"Zone cashier (new)") -> 1 | D8: =COUNTIFS('Daily Log'!$C$5:$C$4004,A8,'Daily Log'!$A$5:$A$4004,">="&Settings!$B$5,'Daily Log'!$A$5:$A$4004,"<="&Settings!$B$6) -> 2 | E8: =COUNTIFS('Daily Log'!$C$5:$C$4004,A8,'Daily Log'!$A$5:$A$4004,">="&Settings!$B$5,'Daily Log'!$A$5:$A$4004,"<="&Settings!$B$6,'Daily Log'!$E$5:$E$4004,"Yes") -> 0 | F8: =IF(D8=0,"",E8/D8) -> 0 | G8: =SUMIFS('Daily Log'!$H$5:$H$4004,'Daily Log'!$C$5:$C$4004,A8,'Daily Log'!$A$5:$A$4004,">="&Settings!$B$5,'Daily Log'!$A$5:$A$4004,"<="&Settings!$B$6,'Daily Log'!$E$5:$E$4004,"Yes") -> 0 | H8: =SUMIFS('Daily Log'!$I$5:$I$4004,'Daily Log'!$C$5:$C$4004,A8,'Daily Log'!$A$5:$A$4004,">="&Settings!$B$5,'Daily Log'!$A$5:$A$4004,"<="&Settings!$B$6,'Daily Log'!$E$5:$E$4004,"Yes") -> 0 | I8: =SUMIFS('Daily Log'!$J$5:$J$4004,'Daily Log'!$C$5:$C$4004,A8,'Daily Log'!$A$5:$A$4004,">="&Settings!$B$5,'Daily Log'!$A$5:$A$4004,"<="&Settings!$B$6,'Daily Log'!$E$5:$E$4004,"Yes") -> 0 | J8: =SUMIFS('Daily Log'!$K$5:$K$4004,'Daily Log'!$C$5:$C$4004,A8,'Daily Log'!$A$5:$A$4004,">="&Settings!$B$5,'Daily Log'!$A$5:$A$4004,"<="&Settings!$B$6,'Daily Log'!$E$5:$E$4004,"Yes") -> 0 | K8: =IF(B8=0,"",H8/B8) -> 0 | M8: =IF(N(L8)=0,"",H8/L8)
A9: Apapa | B9: =COUNTIFS('Cashier Roster'!$C$5:$C$64,A9,'Cashier Roster'!$H$5:$H$64,"Active") -> 2 | C9: =COUNTIFS('Cashier Roster'!$C$5:$C$64,A9,'Cashier Roster'!$H$5:$H$64,"Active",'Cashier Roster'!$D$5:$D$64,"Zone cashier (new)") -> 1 | D9: =COUNTIFS('Daily Log'!$C$5:$C$4004,A9,'Daily Log'!$A$5:$A$4004,">="&Settings!$B$5,'Daily Log'!$A$5:$A$4004,"<="&Settings!$B$6) -> 2 | E9: =COUNTIFS('Daily Log'!$C$5:$C$4004,A9,'Daily Log'!$A$5:$A$4004,">="&Settings!$B$5,'Daily Log'!$A$5:$A$4004,"<="&Settings!$B$6,'Daily Log'!$E$5:$E$4004,"Yes") -> 0 | F9: =IF(D9=0,"",E9/D9) -> 0 | G9: =SUMIFS('Daily Log'!$H$5:$H$4004,'Daily Log'!$C$5:$C$4004,A9,'Daily Log'!$A$5:$A$4004,">="&Settings!$B$5,'Daily Log'!$A$5:$A$4004,"<="&Settings!$B$6,'Daily Log'!$E$5:$E$4004,"Yes") -> 0 | H9: =SUMIFS('Daily Log'!$I$5:$I$4004,'Daily Log'!$C$5:$C$4004,A9,'Daily Log'!$A$5:$A$4004,">="&Settings!$B$5,'Daily Log'!$A$5:$A$4004,"<="&Settings!$B$6,'Daily Log'!$E$5:$E$4004,"Yes") -> 0 | I9: =SUMIFS('Daily Log'!$J$5:$J$4004,'Daily Log'!$C$5:$C$4004,A9,'Daily Log'!$A$5:$A$4004,">="&Settings!$B$5,'Daily Log'!$A$5:$A$4004,"<="&Settings!$B$6,'Daily Log'!$E$5:$E$4004,"Yes") -> 0 | J9: =SUMIFS('Daily Log'!$K$5:$K$4004,'Daily Log'!$C$5:$C$4004,A9,'Daily Log'!$A$5:$A$4004,">="&Settings!$B$5,'Daily Log'!$A$5:$A$4004,"<="&Settings!$B$6,'Daily Log'!$E$5:$E$4004,"Yes") -> 0 | K9: =IF(B9=0,"",H9/B9) -> 0 | M9: =IF(N(L9)=0,"",H9/L9)
A10: Festac | B10: =COUNTIFS('Cashier Roster'!$C$5:$C$64,A10,'Cashier Roster'!$H$5:$H$64,"Active") -> 2 | C10: =COUNTIFS('Cashier Roster'!$C$5:$C$64,A10,'Cashier Roster'!$H$5:$H$64,"Active",'Cashier Roster'!$D$5:$D$64,"Zone cashier (new)") -> 1 | D10: =COUNTIFS('Daily Log'!$C$5:$C$4004,A10,'Daily Log'!$A$5:$A$4004,">="&Settings!$B$5,'Daily Log'!$A$5:$A$4004,"<="&Settings!$B$6) -> 2 | E10: =COUNTIFS('Daily Log'!$C$5:$C$4004,A10,'Daily Log'!$A$5:$A$4004,">="&Settings!$B$5,'Daily Log'!$A$5:$A$4004,"<="&Settings!$B$6,'Daily Log'!$E$5:$E$4004,"Yes") -> 0 | F10: =IF(D10=0,"",E10/D10) -> 0 | G10: =SUMIFS('Daily Log'!$H$5:$H$4004,'Daily Log'!$C$5:$C$4004,A10,'Daily Log'!$A$5:$A$4004,">="&Settings!$B$5,'Daily Log'!$A$5:$A$4004,"<="&Settings!$B$6,'Daily Log'!$E$5:$E$4004,"Yes") -> 0 | H10: =SUMIFS('Daily Log'!$I$5:$I$4004,'Daily Log'!$C$5:$C$4004,A10,'Daily Log'!$A$5:$A$4004,">="&Settings!$B$5,'Daily Log'!$A$5:$A$4004,"<="&Settings!$B$6,'Daily Log'!$E$5:$E$4004,"Yes") -> 0 | I10: =SUMIFS('Daily Log'!$J$5:$J$4004,'Daily Log'!$C$5:$C$4004,A10,'Daily Log'!$A$5:$A$4004,">="&Settings!$B$5,'Daily Log'!$A$5:$A$4004,"<="&Settings!$B$6,'Daily Log'!$E$5:$E$4004,"Yes") -> 0 | J10: =SUMIFS('Daily Log'!$K$5:$K$4004,'Daily Log'!$C$5:$C$4004,A10,'Daily Log'!$A$5:$A$4004,">="&Settings!$B$5,'Daily Log'!$A$5:$A$4004,"<="&Settings!$B$6,'Daily Log'!$E$5:$E$4004,"Yes") -> 0 | K10: =IF(B10=0,"",H10/B10) -> 0 | M10: =IF(N(L10)=0,"",H10/L10)
A11: Ibeju | B11: =COUNTIFS('Cashier Roster'!$C$5:$C$64,A11,'Cashier Roster'!$H$5:$H$64,"Active") -> 1 | C11: =COUNTIFS('Cashier Roster'!$C$5:$C$64,A11,'Cashier Roster'!$H$5:$H$64,"Active",'Cashier Roster'!$D$5:$D$64,"Zone cashier (new)") -> 0 | D11: =COUNTIFS('Daily Log'!$C$5:$C$4004,A11,'Daily Log'!$A$5:$A$4004,">="&Settings!$B$5,'Daily Log'!$A$5:$A$4004,"<="&Settings!$B$6) -> 1 | E11: =COUNTIFS('Daily Log'!$C$5:$C$4004,A11,'Daily Log'!$A$5:$A$4004,">="&Settings!$B$5,'Daily Log'!$A$5:$A$4004,"<="&Settings!$B$6,'Daily Log'!$E$5:$E$4004,"Yes") -> 0 | F11: =IF(D11=0,"",E11/D11) -> 0 | G11: =SUMIFS('Daily Log'!$H$5:$H$4004,'Daily Log'!$C$5:$C$4004,A11,'Daily Log'!$A$5:$A$4004,">="&Settings!$B$5,'Daily Log'!$A$5:$A$4004,"<="&Settings!$B$6,'Daily Log'!$E$5:$E$4004,"Yes") -> 0 | H11: =SUMIFS('Daily Log'!$I$5:$I$4004,'Daily Log'!$C$5:$C$4004,A11,'Daily Log'!$A$5:$A$4004,">="&Settings!$B$5,'Daily Log'!$A$5:$A$4004,"<="&Settings!$B$6,'Daily Log'!$E$5:$E$4004,"Yes") -> 0 | I11: =SUMIFS('Daily Log'!$J$5:$J$4004,'Daily Log'!$C$5:$C$4004,A11,'Daily Log'!$A$5:$A$4004,">="&Settings!$B$5,'Daily Log'!$A$5:$A$4004,"<="&Settings!$B$6,'Daily Log'!$E$5:$E$4004,"Yes") -> 0 | J11: =SUMIFS('Daily Log'!$K$5:$K$4004,'Daily Log'!$C$5:$C$4004,A11,'Daily Log'!$A$5:$A$4004,">="&Settings!$B$5,'Daily Log'!$A$5:$A$4004,"<="&Settings!$B$6,'Daily Log'!$E$5:$E$4004,"Yes") -> 0 | K11: =IF(B11=0,"",H11/B11) -> 0 | M11: =IF(N(L11)=0,"",H11/L11)
A12: Ijora | B12: =COUNTIFS('Cashier Roster'!$C$5:$C$64,A12,'Cashier Roster'!$H$5:$H$64,"Active") -> 2 | C12: =COUNTIFS('Cashier Roster'!$C$5:$C$64,A12,'Cashier Roster'!$H$5:$H$64,"Active",'Cashier Roster'!$D$5:$D$64,"Zone cashier (new)") -> 1 | D12: =COUNTIFS('Daily Log'!$C$5:$C$4004,A12,'Daily Log'!$A$5:$A$4004,">="&Settings!$B$5,'Daily Log'!$A$5:$A$4004,"<="&Settings!$B$6) -> 2 | E12: =COUNTIFS('Daily Log'!$C$5:$C$4004,A12,'Daily Log'!$A$5:$A$4004,">="&Settings!$B$5,'Daily Log'!$A$5:$A$4004,"<="&Settings!$B$6,'Daily Log'!$E$5:$E$4004,"Yes") -> 0 | F12: =IF(D12=0,"",E12/D12) -> 0 | G12: =SUMIFS('Daily Log'!$H$5:$H$4004,'Daily Log'!$C$5:$C$4004,A12,'Daily Log'!$A$5:$A$4004,">="&Settings!$B$5,'Daily Log'!$A$5:$A$4004,"<="&Settings!$B$6,'Daily Log'!$E$5:$E$4004,"Yes") -> 0 | H12: =SUMIFS('Daily Log'!$I$5:$I$4004,'Daily Log'!$C$5:$C$4004,A12,'Daily Log'!$A$5:$A$4004,">="&Settings!$B$5,'Daily Log'!$A$5:$A$4004,"<="&Settings!$B$6,'Daily Log'!$E$5:$E$4004,"Yes") -> 0 | I12: =SUMIFS('Daily Log'!$J$5:$J$4004,'Daily Log'!$C$5:$C$4004,A12,'Daily Log'!$A$5:$A$4004,">="&Settings!$B$5,'Daily Log'!$A$5:$A$4004,"<="&Settings!$B$6,'Daily Log'!$E$5:$E$4004,"Yes") -> 0 | J12: =SUMIFS('Daily Log'!$K$5:$K$4004,'Daily Log'!$C$5:$C$4004,A12,'Daily Log'!$A$5:$A$4004,">="&Settings!$B$5,'Daily Log'!$A$5:$A$4004,"<="&Settings!$B$6,'Daily Log'!$E$5:$E$4004,"Yes") -> 0 | K12: =IF(B12=0,"",H12/B12) -> 0 | M12: =IF(N(L12)=0,"",H12/L12)
A13: Island | B13: =COUNTIFS('Cashier Roster'!$C$5:$C$64,A13,'Cashier Roster'!$H$5:$H$64,"Active") -> 2 | C13: =COUNTIFS('Cashier Roster'!$C$5:$C$64,A13,'Cashier Roster'!$H$5:$H$64,"Active",'Cashier Roster'!$D$5:$D$64,"Zone cashier (new)") -> 0 | D13: =COUNTIFS('Daily Log'!$C$5:$C$4004,A13,'Daily Log'!$A$5:$A$4004,">="&Settings!$B$5,'Daily Log'!$A$5:$A$4004,"<="&Settings!$B$6) -> 2 | E13: =COUNTIFS('Daily Log'!$C$5:$C$4004,A13,'Daily Log'!$A$5:$A$4004,">="&Settings!$B$5,'Daily Log'!$A$5:$A$4004,"<="&Settings!$B$6,'Daily Log'!$E$5:$E$4004,"Yes") -> 0 | F13: =IF(D13=0,"",E13/D13) -> 0 | G13: =SUMIFS('Daily Log'!$H$5:$H$4004,'Daily Log'!$C$5:$C$4004,A13,'Daily Log'!$A$5:$A$4004,">="&Settings!$B$5,'Daily Log'!$A$5:$A$4004,"<="&Settings!$B$6,'Daily Log'!$E$5:$E$4004,"Yes") -> 0 | H13: =SUMIFS('Daily Log'!$I$5:$I$4004,'Daily Log'!$C$5:$C$4004,A13,'Daily Log'!$A$5:$A$4004,">="&Settings!$B$5,'Daily Log'!$A$5:$A$4004,"<="&Settings!$B$6,'Daily Log'!$E$5:$E$4004,"Yes") -> 0 | I13: =SUMIFS('Daily Log'!$J$5:$J$4004,'Daily Log'!$C$5:$C$4004,A13,'Daily Log'!$A$5:$A$4004,">="&Settings!$B$5,'Daily Log'!$A$5:$A$4004,"<="&Settings!$B$6,'Daily Log'!$E$5:$E$4004,"Yes") -> 0 | J13: =SUMIFS('Daily Log'!$K$5:$K$4004,'Daily Log'!$C$5:$C$4004,A13,'Daily Log'!$A$5:$A$4004,">="&Settings!$B$5,'Daily Log'!$A$5:$A$4004,"<="&Settings!$B$6,'Daily Log'!$E$5:$E$4004,"Yes") -> 0 | K13: =IF(B13=0,"",H13/B13) -> 0 | M13: =IF(N(L13)=0,"",H13/L13)
A14: Lekki | B14: =COUNTIFS('Cashier Roster'!$C$5:$C$64,A14,'Cashier Roster'!$H$5:$H$64,"Active") -> 1 | C14: =COUNTIFS('Cashier Roster'!$C$5:$C$64,A14,'Cashier Roster'!$H$5:$H$64,"Active",'Cashier Roster'!$D$5:$D$64,"Zone cashier (new)") -> 0 | D14: =COUNTIFS('Daily Log'!$C$5:$C$4004,A14,'Daily Log'!$A$5:$A$4004,">="&Settings!$B$5,'Daily Log'!$A$5:$A$4004,"<="&Settings!$B$6) -> 1 | E14: =COUNTIFS('Daily Log'!$C$5:$C$4004,A14,'Daily Log'!$A$5:$A$4004,">="&Settings!$B$5,'Daily Log'!$A$5:$A$4004,"<="&Settings!$B$6,'Daily Log'!$E$5:$E$4004,"Yes") -> 0 | F14: =IF(D14=0,"",E14/D14) -> 0 | G14: =SUMIFS('Daily Log'!$H$5:$H$4004,'Daily Log'!$C$5:$C$4004,A14,'Daily Log'!$A$5:$A$4004,">="&Settings!$B$5,'Daily Log'!$A$5:$A$4004,"<="&Settings!$B$6,'Daily Log'!$E$5:$E$4004,"Yes") -> 0 | H14: =SUMIFS('Daily Log'!$I$5:$I$4004,'Daily Log'!$C$5:$C$4004,A14,'Daily Log'!$A$5:$A$4004,">="&Settings!$B$5,'Daily Log'!$A$5:$A$4004,"<="&Settings!$B$6,'Daily Log'!$E$5:$E$4004,"Yes") -> 0 | I14: =SUMIFS('Daily Log'!$J$5:$J$4004,'Daily Log'!$C$5:$C$4004,A14,'Daily Log'!$A$5:$A$4004,">="&Settings!$B$5,'Daily Log'!$A$5:$A$4004,"<="&Settings!$B$6,'Daily Log'!$E$5:$E$4004,"Yes") -> 0 | J14: =SUMIFS('Daily Log'!$K$5:$K$4004,'Daily Log'!$C$5:$C$4004,A14,'Daily Log'!$A$5:$A$4004,">="&Settings!$B$5,'Daily Log'!$A$5:$A$4004,"<="&Settings!$B$6,'Daily Log'!$E$5:$E$4004,"Yes") -> 0 | K14: =IF(B14=0,"",H14/B14) -> 0 | M14: =IF(N(L14)=0,"",H14/L14)
A15: Mushin | B15: =COUNTIFS('Cashier Roster'!$C$5:$C$64,A15,'Cashier Roster'!$H$5:$H$64,"Active") -> 2 | C15: =COUNTIFS('Cashier Roster'!$C$5:$C$64,A15,'Cashier Roster'!$H$5:$H$64,"Active",'Cashier Roster'!$D$5:$D$64,"Zone cashier (new)") -> 1 | D15: =COUNTIFS('Daily Log'!$C$5:$C$4004,A15,'Daily Log'!$A$5:$A$4004,">="&Settings!$B$5,'Daily Log'!$A$5:$A$4004,"<="&Settings!$B$6) -> 2 | E15: =COUNTIFS('Daily Log'!$C$5:$C$4004,A15,'Daily Log'!$A$5:$A$4004,">="&Settings!$B$5,'Daily Log'!$A$5:$A$4004,"<="&Settings!$B$6,'Daily Log'!$E$5:$E$4004,"Yes") -> 0 | F15: =IF(D15=0,"",E15/D15) -> 0 | G15: =SUMIFS('Daily Log'!$H$5:$H$4004,'Daily Log'!$C$5:$C$4004,A15,'Daily Log'!$A$5:$A$4004,">="&Settings!$B$5,'Daily Log'!$A$5:$A$4004,"<="&Settings!$B$6,'Daily Log'!$E$5:$E$4004,"Yes") -> 0 | H15: =SUMIFS('Daily Log'!$I$5:$I$4004,'Daily Log'!$C$5:$C$4004,A15,'Daily Log'!$A$5:$A$4004,">="&Settings!$B$5,'Daily Log'!$A$5:$A$4004,"<="&Settings!$B$6,'Daily Log'!$E$5:$E$4004,"Yes") -> 0 | I15: =SUMIFS('Daily Log'!$J$5:$J$4004,'Daily Log'!$C$5:$C$4004,A15,'Daily Log'!$A$5:$A$4004,">="&Settings!$B$5,'Daily Log'!$A$5:$A$4004,"<="&Settings!$B$6,'Daily Log'!$E$5:$E$4004,"Yes") -> 0 | J15: =SUMIFS('Daily Log'!$K$5:$K$4004,'Daily Log'!$C$5:$C$4004,A15,'Daily Log'!$A$5:$A$4004,">="&Settings!$B$5,'Daily Log'!$A$5:$A$4004,"<="&Settings!$B$6,'Daily Log'!$E$5:$E$4004,"Yes") -> 0 | K15: =IF(B15=0,"",H15/B15) -> 0 | M15: =IF(N(L15)=0,"",H15/L15)
